Traceback (most recent call last):
  File "/Users/aet/mambaforge/envs/codeforecon/lib/python3.10/site-packages/jupyter_cache/executors/utils.py", line 58, in single_nb_execution
    executenb(
  File "/Users/aet/mambaforge/envs/codeforecon/lib/python3.10/site-packages/nbclient/client.py", line 1305, in execute
    return NotebookClient(nb=nb, resources=resources, km=km, **kwargs).execute()
  File "/Users/aet/mambaforge/envs/codeforecon/lib/python3.10/site-packages/jupyter_core/utils/__init__.py", line 166, in wrapped
    return loop.run_until_complete(inner)
  File "/Users/aet/mambaforge/envs/codeforecon/lib/python3.10/asyncio/base_events.py", line 649, in run_until_complete
    return future.result()
  File "/Users/aet/mambaforge/envs/codeforecon/lib/python3.10/site-packages/nbclient/client.py", line 705, in async_execute
    await self.async_execute_cell(
  File "/Users/aet/mambaforge/envs/codeforecon/lib/python3.10/site-packages/nbclient/client.py", line 1058, in async_execute_cell
    await self._check_raise_for_error(cell, cell_index, exec_reply)
  File "/Users/aet/mambaforge/envs/codeforecon/lib/python3.10/site-packages/nbclient/client.py", line 914, in _check_raise_for_error
    raise CellExecutionError.from_cell_and_msg(cell, exec_reply_content)
nbclient.exceptions.CellExecutionError: An error occurred while executing the following cell:
------------------
df["cat_type"].cat.categories = ["alpha", "beta", "gamma"]
df
------------------


[0;31m---------------------------------------------------------------------------[0m
[0;31mAttributeError[0m                            Traceback (most recent call last)
Cell [0;32mIn[10], line 1[0m
[0;32m----> 1[0m [43mdf[49m[43m[[49m[38;5;124;43m"[39;49m[38;5;124;43mcat_type[39;49m[38;5;124;43m"[39;49m[43m][49m[38;5;241;43m.[39;49m[43mcat[49m[38;5;241;43m.[39;49m[43mcategories[49m [38;5;241m=[39m [[38;5;124m"[39m[38;5;124malpha[39m[38;5;124m"[39m, [38;5;124m"[39m[38;5;124mbeta[39m[38;5;124m"[39m, [38;5;124m"[39m[38;5;124mgamma[39m[38;5;124m"[39m]
[1;32m      2[0m df

File [0;32m~/mambaforge/envs/codeforecon/lib/python3.10/site-packages/pandas/core/base.py:178[0m, in [0;36mNoNewAttributesMixin.__setattr__[0;34m(self, key, value)[0m
[1;32m    172[0m [38;5;28;01mif[39;00m [38;5;28mgetattr[39m([38;5;28mself[39m, [38;5;124m"[39m[38;5;124m__frozen[39m[38;5;124m"[39m, [38;5;28;01mFalse[39;00m) [38;5;129;01mand[39;00m [38;5;129;01mnot[39;00m (
[1;32m    173[0m     key [38;5;241m==[39m [38;5;124m"[39m[38;5;124m_cache[39m[38;5;124m"[39m
[1;32m    174[0m     [38;5;129;01mor[39;00m key [38;5;129;01min[39;00m [38;5;28mtype[39m([38;5;28mself[39m)[38;5;241m.[39m[38;5;18m__dict__[39m
[1;32m    175[0m     [38;5;129;01mor[39;00m [38;5;28mgetattr[39m([38;5;28mself[39m, key, [38;5;28;01mNone[39;00m) [38;5;129;01mis[39;00m [38;5;129;01mnot[39;00m [38;5;28;01mNone[39;00m
[1;32m    176[0m ):
[1;32m    177[0m     [38;5;28;01mraise[39;00m [38;5;167;01mAttributeError[39;00m([38;5;124mf[39m[38;5;124m"[39m[38;5;124mYou cannot add any new attribute [39m[38;5;124m'[39m[38;5;132;01m{[39;00mkey[38;5;132;01m}[39;00m[38;5;124m'[39m[38;5;124m"[39m)
[0;32m--> 178[0m [38;5;28;43mobject[39;49m[38;5;241;43m.[39;49m[38;5;21;43m__setattr__[39;49m[43m([49m[38;5;28;43mself[39;49m[43m,[49m[43m [49m[43mkey[49m[43m,[49m[43m [49m[43mvalue[49m[43m)[49m

File [0;32m~/mambaforge/envs/codeforecon/lib/python3.10/site-packages/pandas/core/accessor.py:99[0m, in [0;36mPandasDelegate._add_delegate_accessors.<locals>._create_delegator_property.<locals>._setter[0;34m(self, new_values)[0m
[1;32m     98[0m [38;5;28;01mdef[39;00m [38;5;21m_setter[39m([38;5;28mself[39m, new_values):
[0;32m---> 99[0m     [38;5;28;01mreturn[39;00m [38;5;28;43mself[39;49m[38;5;241;43m.[39;49m[43m_delegate_property_set[49m[43m([49m[43mname[49m[43m,[49m[43m [49m[43mnew_values[49m[43m)[49m

File [0;32m~/mambaforge/envs/codeforecon/lib/python3.10/site-packages/pandas/core/arrays/categorical.py:2460[0m, in [0;36mCategoricalAccessor._delegate_property_set[0;34m(self, name, new_values)[0m
[1;32m   2459[0m [38;5;28;01mdef[39;00m [38;5;21m_delegate_property_set[39m([38;5;28mself[39m, name, new_values):
[0;32m-> 2460[0m     [38;5;28;01mreturn[39;00m [38;5;28;43msetattr[39;49m[43m([49m[38;5;28;43mself[39;49m[38;5;241;43m.[39;49m[43m_parent[49m[43m,[49m[43m [49m[43mname[49m[43m,[49m[43m [49m[43mnew_values[49m[43m)[49m

[0;31mAttributeError[0m: can't set attribute 'categories'

