Traceback (most recent call last):
  File "/opt/anaconda3/envs/codeforecon/lib/python3.8/site-packages/jupyter_cache/executors/utils.py", line 51, in single_nb_execution
    executenb(
  File "/opt/anaconda3/envs/codeforecon/lib/python3.8/site-packages/nbclient/client.py", line 1204, in execute
    return NotebookClient(nb=nb, resources=resources, km=km, **kwargs).execute()
  File "/opt/anaconda3/envs/codeforecon/lib/python3.8/site-packages/nbclient/util.py", line 84, in wrapped
    return just_run(coro(*args, **kwargs))
  File "/opt/anaconda3/envs/codeforecon/lib/python3.8/site-packages/nbclient/util.py", line 62, in just_run
    return loop.run_until_complete(coro)
  File "/opt/anaconda3/envs/codeforecon/lib/python3.8/asyncio/base_events.py", line 616, in run_until_complete
    return future.result()
  File "/opt/anaconda3/envs/codeforecon/lib/python3.8/site-packages/nbclient/client.py", line 663, in async_execute
    await self.async_execute_cell(
  File "/opt/anaconda3/envs/codeforecon/lib/python3.8/site-packages/nbclient/client.py", line 965, in async_execute_cell
    await self._check_raise_for_error(cell, cell_index, exec_reply)
  File "/opt/anaconda3/envs/codeforecon/lib/python3.8/site-packages/nbclient/client.py", line 862, in _check_raise_for_error
    raise CellExecutionError.from_cell_and_msg(cell, exec_reply_content)
nbclient.exceptions.CellExecutionError: An error occurred while executing the following cell:
------------------
# Construct the exponential smoothing model
ets_mod = sm.tsa.statespace.ExponentialSmoothing(
    df, trend=True, seasonal=7,
    initialization_method='concentrated')

# Fit the parameters of the model
ets_res = ets_mod.fit()

ets_seasonal = ets_res.states.smoothed['seasonal.0']
ets_trend = ets_res.states.smoothed['level']
ets_resid = ets_res.states.smoothed["error"]
------------------

[0;31m---------------------------------------------------------------------------[0m
[0;31mKeyError[0m                                  Traceback (most recent call last)
File [0;32m/opt/anaconda3/envs/codeforecon/lib/python3.8/site-packages/pandas/core/indexes/base.py:3629[0m, in [0;36mIndex.get_loc[0;34m(self, key, method, tolerance)[0m
[1;32m   3628[0m [38;5;28;01mtry[39;00m:
[0;32m-> 3629[0m     [38;5;28;01mreturn[39;00m [38;5;28;43mself[39;49m[38;5;241;43m.[39;49m[43m_engine[49m[38;5;241;43m.[39;49m[43mget_loc[49m[43m([49m[43mcasted_key[49m[43m)[49m
[1;32m   3630[0m [38;5;28;01mexcept[39;00m [38;5;167;01mKeyError[39;00m [38;5;28;01mas[39;00m err:

File [0;32m/opt/anaconda3/envs/codeforecon/lib/python3.8/site-packages/pandas/_libs/index.pyx:136[0m, in [0;36mpandas._libs.index.IndexEngine.get_loc[0;34m()[0m

File [0;32m/opt/anaconda3/envs/codeforecon/lib/python3.8/site-packages/pandas/_libs/index.pyx:163[0m, in [0;36mpandas._libs.index.IndexEngine.get_loc[0;34m()[0m

File [0;32mpandas/_libs/hashtable_class_helper.pxi:5198[0m, in [0;36mpandas._libs.hashtable.PyObjectHashTable.get_item[0;34m()[0m

File [0;32mpandas/_libs/hashtable_class_helper.pxi:5206[0m, in [0;36mpandas._libs.hashtable.PyObjectHashTable.get_item[0;34m()[0m

[0;31mKeyError[0m: 'seasonal.0'

The above exception was the direct cause of the following exception:

[0;31mKeyError[0m                                  Traceback (most recent call last)
Input [0;32mIn [57][0m, in [0;36m<cell line: 9>[0;34m()[0m
[1;32m      6[0m [38;5;66;03m# Fit the parameters of the model[39;00m
[1;32m      7[0m ets_res [38;5;241m=[39m ets_mod[38;5;241m.[39mfit()
[0;32m----> 9[0m ets_seasonal [38;5;241m=[39m [43mets_res[49m[38;5;241;43m.[39;49m[43mstates[49m[38;5;241;43m.[39;49m[43msmoothed[49m[43m[[49m[38;5;124;43m'[39;49m[38;5;124;43mseasonal.0[39;49m[38;5;124;43m'[39;49m[43m][49m
[1;32m     10[0m ets_trend [38;5;241m=[39m ets_res[38;5;241m.[39mstates[38;5;241m.[39msmoothed[[38;5;124m'[39m[38;5;124mlevel[39m[38;5;124m'[39m]
[1;32m     11[0m ets_resid [38;5;241m=[39m ets_res[38;5;241m.[39mstates[38;5;241m.[39msmoothed[[38;5;124m"[39m[38;5;124merror[39m[38;5;124m"[39m]

File [0;32m/opt/anaconda3/envs/codeforecon/lib/python3.8/site-packages/pandas/core/frame.py:3505[0m, in [0;36mDataFrame.__getitem__[0;34m(self, key)[0m
[1;32m   3503[0m [38;5;28;01mif[39;00m [38;5;28mself[39m[38;5;241m.[39mcolumns[38;5;241m.[39mnlevels [38;5;241m>[39m [38;5;241m1[39m:
[1;32m   3504[0m     [38;5;28;01mreturn[39;00m [38;5;28mself[39m[38;5;241m.[39m_getitem_multilevel(key)
[0;32m-> 3505[0m indexer [38;5;241m=[39m [38;5;28;43mself[39;49m[38;5;241;43m.[39;49m[43mcolumns[49m[38;5;241;43m.[39;49m[43mget_loc[49m[43m([49m[43mkey[49m[43m)[49m
[1;32m   3506[0m [38;5;28;01mif[39;00m is_integer(indexer):
[1;32m   3507[0m     indexer [38;5;241m=[39m [indexer]

File [0;32m/opt/anaconda3/envs/codeforecon/lib/python3.8/site-packages/pandas/core/indexes/base.py:3631[0m, in [0;36mIndex.get_loc[0;34m(self, key, method, tolerance)[0m
[1;32m   3629[0m     [38;5;28;01mreturn[39;00m [38;5;28mself[39m[38;5;241m.[39m_engine[38;5;241m.[39mget_loc(casted_key)
[1;32m   3630[0m [38;5;28;01mexcept[39;00m [38;5;167;01mKeyError[39;00m [38;5;28;01mas[39;00m err:
[0;32m-> 3631[0m     [38;5;28;01mraise[39;00m [38;5;167;01mKeyError[39;00m(key) [38;5;28;01mfrom[39;00m [38;5;21;01merr[39;00m
[1;32m   3632[0m [38;5;28;01mexcept[39;00m [38;5;167;01mTypeError[39;00m:
[1;32m   3633[0m     [38;5;66;03m# If we have a listlike key, _check_indexing_error will raise[39;00m
[1;32m   3634[0m     [38;5;66;03m#  InvalidIndexError. Otherwise we fall through and re-raise[39;00m
[1;32m   3635[0m     [38;5;66;03m#  the TypeError.[39;00m
[1;32m   3636[0m     [38;5;28mself[39m[38;5;241m.[39m_check_indexing_error(key)

[0;31mKeyError[0m: 'seasonal.0'
KeyError: 'seasonal.0'

