Traceback (most recent call last):
  File "/opt/anaconda3/envs/codeforecon/lib/python3.8/site-packages/jupyter_cache/executors/utils.py", line 51, in single_nb_execution
    executenb(
  File "/opt/anaconda3/envs/codeforecon/lib/python3.8/site-packages/nbclient/client.py", line 1204, in execute
    return NotebookClient(nb=nb, resources=resources, km=km, **kwargs).execute()
  File "/opt/anaconda3/envs/codeforecon/lib/python3.8/site-packages/nbclient/util.py", line 84, in wrapped
    return just_run(coro(*args, **kwargs))
  File "/opt/anaconda3/envs/codeforecon/lib/python3.8/site-packages/nbclient/util.py", line 62, in just_run
    return loop.run_until_complete(coro)
  File "/opt/anaconda3/envs/codeforecon/lib/python3.8/asyncio/base_events.py", line 616, in run_until_complete
    return future.result()
  File "/opt/anaconda3/envs/codeforecon/lib/python3.8/site-packages/nbclient/client.py", line 663, in async_execute
    await self.async_execute_cell(
  File "/opt/anaconda3/envs/codeforecon/lib/python3.8/site-packages/nbclient/client.py", line 965, in async_execute_cell
    await self._check_raise_for_error(cell, cell_index, exec_reply)
  File "/opt/anaconda3/envs/codeforecon/lib/python3.8/site-packages/nbclient/client.py", line 862, in _check_raise_for_error
    raise CellExecutionError.from_cell_and_msg(cell, exec_reply_content)
nbclient.exceptions.CellExecutionError: An error occurred while executing the following cell:
------------------
n_connects = 60
flux = np.array(
    [
        np.random.choice(range(10), n_connects),
        np.random.choice(range(10), n_connects),
        np.random.choice(range(10), n_connects),
    ]
)
links = pd.DataFrame(flux.T, columns=["source", "target", "value"])
# if source and target the same, drop rows
links = links[links["source"] != links["target"]]
nodes = pd.DataFrame.from_dict(
    {
        "source": range(10),
        "city": [
            "London",
            "Manchester",
            "Birmingham",
            "Leeds",
            "Sheffield",
            "Bradford",
            "Liverpool",
            "Bristol",
            "Newcastle",
            "Sunderland",
        ],
        "index": range(10),
    }
)
nodes = hv.Dataset(nodes, "index")
links
------------------

[0;31m---------------------------------------------------------------------------[0m
[0;31mNameError[0m                                 Traceback (most recent call last)
Input [0;32mIn [126][0m, in [0;36m<cell line: 30>[0;34m()[0m
[1;32m     11[0m links [38;5;241m=[39m links[links[[38;5;124m"[39m[38;5;124msource[39m[38;5;124m"[39m] [38;5;241m!=[39m links[[38;5;124m"[39m[38;5;124mtarget[39m[38;5;124m"[39m]]
[1;32m     12[0m nodes [38;5;241m=[39m pd[38;5;241m.[39mDataFrame[38;5;241m.[39mfrom_dict(
[1;32m     13[0m     {
[1;32m     14[0m         [38;5;124m"[39m[38;5;124msource[39m[38;5;124m"[39m: [38;5;28mrange[39m([38;5;241m10[39m),
[0;32m   (...)[0m
[1;32m     28[0m     }
[1;32m     29[0m )
[0;32m---> 30[0m nodes [38;5;241m=[39m [43mhv[49m[38;5;241m.[39mDataset(nodes, [38;5;124m"[39m[38;5;124mindex[39m[38;5;124m"[39m)
[1;32m     31[0m links

[0;31mNameError[0m: name 'hv' is not defined
NameError: name 'hv' is not defined

